from discord.ext import commands
import discord

class TestErrorCog(commands.Cog):
    def __init__(self, bot):
        self.bot = bot

    @commands.command(name='test')
    async def test_error_command(self, ctx, error_type: str):
        if error_type == "CommandNotFound":
            raise commands.CommandNotFound("これはテスト用のコマンドが見つからないエラーです。")
        elif error_type == "MissingRequiredArgument":
            raise commands.MissingRequiredArgument(param=None)
        elif error_type == "TooManyArguments":
            raise commands.TooManyArguments("引数が多すぎます。")
        elif error_type == "BadArgument":
            raise commands.BadArgument("無効な引数が提供されました。")
        elif error_type == "NoPrivateMessage":
            raise commands.NoPrivateMessage("このコマンドはプライベートメッセージでは使用できません。")
        elif error_type == "PrivateMessageOnly":
            raise commands.PrivateMessageOnly("このコマンドはプライベートメッセージでのみ使用できます。")
        elif error_type == "NotOwner":
            raise commands.NotOwner("このコマンドはBotのオーナーのみが使用できます。")
        elif error_type == "MissingPermissions":
            # MissingPermissions エラーは通常、特定の権限が欠けている場合に発生します。
            # この例ではダミーの権限リストを使用していますが、実際には適切な権限を指定する必要があります。
            raise commands.MissingPermissions(["manage_messages"])
        elif error_type == "BotMissingPermissions":
            # BotMissingPermissions エラーはBotが必要とする権限が欠けている場合に発生します。
            # この例ではダミーの権限リストを使用していますが、実際には適切な権限を指定する必要があります。
            raise commands.BotMissingPermissions(["manage_messages"])
        elif error_type == "CheckFailure":
            raise commands.CheckFailure("コマンドの前提条件を満たしていません。")
        elif error_type == "CommandOnCooldown":
            # CommandOnCooldown エラーはコマンドがクールダウン中に再度実行された場合に発生します。
            # この例ではダミーの再試行時間を設定していますが、実際には適切な設定が必要です。
            raise commands.CommandOnCooldown(cooldown=discord.Cooldown(rate=1, per=30, type=commands.BucketType.user), retry_after=30)
        elif error_type == "DisabledCommand":
            raise commands.DisabledCommand("このコマンドは現在無効になっています。")
        elif error_type == "CommandInvokeError":
            # CommandInvokeError エラーはコマンドの実行中に発生したエラーをラップするために使用されます。
            # この例では単純なRuntimeErrorを発生させていますが、実際にはさまざまな原因が考えられます。
            raise commands.CommandInvokeError(original=RuntimeError("コマンド実行中にエラーが発生しました。"))

        else:
            await ctx.respond(f"指定されたエラータイプ `{error_type}` はサポートされていません。", ephemeral=True)

async def setup(bot):
    await bot.add_cog(TestErrorCog(bot))
